{
 "cells": [
  {
   "cell_type": "code",
   "execution_count": 21,
   "id": "ba55ede7-0d70-4285-acee-7b7462a02ff6",
   "metadata": {},
   "outputs": [],
   "source": [
    "from tensorflow.keras.preprocessing.image import load_img, img_to_array\n",
    "from tensorflow.keras.applications.resnet50 import ResNet50, preprocess_input\n",
    "from tensorflow.keras.layers import Flatten"
   ]
  },
  {
   "cell_type": "markdown",
   "id": "34880037-38a8-4a7e-835e-121bdce79177",
   "metadata": {},
   "source": [
    "## Image encoder"
   ]
  },
  {
   "cell_type": "code",
   "execution_count": 15,
   "id": "6362ee5e-a6ae-44c4-9ae7-cca8bb261ce1",
   "metadata": {},
   "outputs": [],
   "source": [
    "TARGET_SIZE = (224, 224)"
   ]
  },
  {
   "cell_type": "code",
   "execution_count": 16,
   "id": "bae820ac-ef0f-4799-b6c7-f0058678e331",
   "metadata": {},
   "outputs": [],
   "source": [
    "img_path=\"samples/sample_dress.jpg\""
   ]
  },
  {
   "cell_type": "code",
   "execution_count": 17,
   "id": "0e5e2811-d0d2-4cfb-af3a-377a39a0fde4",
   "metadata": {
    "colab": {
     "base_uri": "https://localhost:8080/"
    },
    "id": "efec3e56-f152-424a-a6d5-75b3ec508570",
    "outputId": "3cb77989-dc0a-4021-aa60-1bd8ef37e733",
    "tags": []
   },
   "outputs": [],
   "source": [
    "# Load the images and convert them to numpy arrays\n",
    "image = load_img(path=img_path, target_size=TARGET_SIZE)\n",
    "input_img = img_to_array(image)"
   ]
  },
  {
   "cell_type": "code",
   "execution_count": 18,
   "id": "2ae78c08-2e83-4a9b-befb-d51d2f7dd357",
   "metadata": {},
   "outputs": [],
   "source": [
    "#input_img = Input(shape=(300, 200, 3)) # Should be an image from file"
   ]
  },
  {
   "cell_type": "code",
   "execution_count": 11,
   "id": "7c692dd5-e5ef-47d2-b748-4c61bab33ef4",
   "metadata": {},
   "outputs": [
    {
     "name": "stderr",
     "output_type": "stream",
     "text": [
      "2023-03-05 15:39:03.470265: I tensorflow/core/platform/cpu_feature_guard.cc:193] This TensorFlow binary is optimized with oneAPI Deep Neural Network Library (oneDNN) to use the following CPU instructions in performance-critical operations:  SSE4.1 SSE4.2 AVX AVX2 FMA\n",
      "To enable them in other operations, rebuild TensorFlow with the appropriate compiler flags.\n"
     ]
    },
    {
     "name": "stdout",
     "output_type": "stream",
     "text": [
      "Downloading data from https://storage.googleapis.com/tensorflow/keras-applications/resnet/resnet50_weights_tf_dim_ordering_tf_kernels_notop.h5\n",
      "94765736/94765736 [==============================] - 5s 0us/step\n"
     ]
    }
   ],
   "source": [
    "resnet_feature_encoder = ResNet50(weights=\"imagenet\", include_top=False)\n",
    "encoded_img = layers.Flatten()(resnet_feature_encoder(input_img))"
   ]
  },
  {
   "cell_type": "code",
   "execution_count": 19,
   "id": "7fcecda5-e532-47d0-b959-318762682b67",
   "metadata": {
    "collapsed": true,
    "jupyter": {
     "outputs_hidden": true
    },
    "tags": []
   },
   "outputs": [
    {
     "name": "stdout",
     "output_type": "stream",
     "text": [
      "WARNING:tensorflow:Model was constructed with shape (None, None, None, 3) for input KerasTensor(type_spec=TensorSpec(shape=(None, None, None, 3), dtype=tf.float32, name='input_1'), name='input_1', description=\"created by layer 'input_1'\"), but it was called on an input with incompatible shape (32, 224, 3).\n"
     ]
    },
    {
     "ename": "ValueError",
     "evalue": "in user code:\n\n    File \"/Users/kuzmatsukanov/opt/anaconda3/lib/python3.9/site-packages/keras/engine/training.py\", line 2041, in predict_function  *\n        return step_function(self, iterator)\n    File \"/Users/kuzmatsukanov/opt/anaconda3/lib/python3.9/site-packages/keras/engine/training.py\", line 2027, in step_function  **\n        outputs = model.distribute_strategy.run(run_step, args=(data,))\n    File \"/Users/kuzmatsukanov/opt/anaconda3/lib/python3.9/site-packages/keras/engine/training.py\", line 2015, in run_step  **\n        outputs = model.predict_step(data)\n    File \"/Users/kuzmatsukanov/opt/anaconda3/lib/python3.9/site-packages/keras/engine/training.py\", line 1983, in predict_step\n        return self(x, training=False)\n    File \"/Users/kuzmatsukanov/opt/anaconda3/lib/python3.9/site-packages/keras/utils/traceback_utils.py\", line 70, in error_handler\n        raise e.with_traceback(filtered_tb) from None\n    File \"/Users/kuzmatsukanov/opt/anaconda3/lib/python3.9/site-packages/keras/engine/input_spec.py\", line 232, in assert_input_compatibility\n        raise ValueError(\n\n    ValueError: Exception encountered when calling layer \"resnet50\" \"                 f\"(type Functional).\n    \n    Input 0 of layer \"conv1_pad\" is incompatible with the layer: expected ndim=4, found ndim=3. Full shape received: (32, 224, 3)\n    \n    Call arguments received by layer \"resnet50\" \"                 f\"(type Functional):\n      • inputs=tf.Tensor(shape=(32, 224, 3), dtype=float32)\n      • training=False\n      • mask=None\n",
     "output_type": "error",
     "traceback": [
      "\u001b[0;31m---------------------------------------------------------------------------\u001b[0m",
      "\u001b[0;31mValueError\u001b[0m                                Traceback (most recent call last)",
      "Cell \u001b[0;32mIn[19], line 1\u001b[0m\n\u001b[0;32m----> 1\u001b[0m \u001b[43mresnet_feature_encoder\u001b[49m\u001b[38;5;241;43m.\u001b[39;49m\u001b[43mpredict\u001b[49m\u001b[43m(\u001b[49m\u001b[43minput_img\u001b[49m\u001b[43m)\u001b[49m\n",
      "File \u001b[0;32m~/opt/anaconda3/lib/python3.9/site-packages/keras/utils/traceback_utils.py:70\u001b[0m, in \u001b[0;36mfilter_traceback.<locals>.error_handler\u001b[0;34m(*args, **kwargs)\u001b[0m\n\u001b[1;32m     67\u001b[0m     filtered_tb \u001b[38;5;241m=\u001b[39m _process_traceback_frames(e\u001b[38;5;241m.\u001b[39m__traceback__)\n\u001b[1;32m     68\u001b[0m     \u001b[38;5;66;03m# To get the full stack trace, call:\u001b[39;00m\n\u001b[1;32m     69\u001b[0m     \u001b[38;5;66;03m# `tf.debugging.disable_traceback_filtering()`\u001b[39;00m\n\u001b[0;32m---> 70\u001b[0m     \u001b[38;5;28;01mraise\u001b[39;00m e\u001b[38;5;241m.\u001b[39mwith_traceback(filtered_tb) \u001b[38;5;28;01mfrom\u001b[39;00m \u001b[38;5;28mNone\u001b[39m\n\u001b[1;32m     71\u001b[0m \u001b[38;5;28;01mfinally\u001b[39;00m:\n\u001b[1;32m     72\u001b[0m     \u001b[38;5;28;01mdel\u001b[39;00m filtered_tb\n",
      "File \u001b[0;32m/var/folders/0y/1dfjgtlj6nj1t5972c1vn3200000gn/T/__autograph_generated_filev9sjonx4.py:15\u001b[0m, in \u001b[0;36mouter_factory.<locals>.inner_factory.<locals>.tf__predict_function\u001b[0;34m(iterator)\u001b[0m\n\u001b[1;32m     13\u001b[0m \u001b[38;5;28;01mtry\u001b[39;00m:\n\u001b[1;32m     14\u001b[0m     do_return \u001b[38;5;241m=\u001b[39m \u001b[38;5;28;01mTrue\u001b[39;00m\n\u001b[0;32m---> 15\u001b[0m     retval_ \u001b[38;5;241m=\u001b[39m ag__\u001b[38;5;241m.\u001b[39mconverted_call(ag__\u001b[38;5;241m.\u001b[39mld(step_function), (ag__\u001b[38;5;241m.\u001b[39mld(\u001b[38;5;28mself\u001b[39m), ag__\u001b[38;5;241m.\u001b[39mld(iterator)), \u001b[38;5;28;01mNone\u001b[39;00m, fscope)\n\u001b[1;32m     16\u001b[0m \u001b[38;5;28;01mexcept\u001b[39;00m:\n\u001b[1;32m     17\u001b[0m     do_return \u001b[38;5;241m=\u001b[39m \u001b[38;5;28;01mFalse\u001b[39;00m\n",
      "\u001b[0;31mValueError\u001b[0m: in user code:\n\n    File \"/Users/kuzmatsukanov/opt/anaconda3/lib/python3.9/site-packages/keras/engine/training.py\", line 2041, in predict_function  *\n        return step_function(self, iterator)\n    File \"/Users/kuzmatsukanov/opt/anaconda3/lib/python3.9/site-packages/keras/engine/training.py\", line 2027, in step_function  **\n        outputs = model.distribute_strategy.run(run_step, args=(data,))\n    File \"/Users/kuzmatsukanov/opt/anaconda3/lib/python3.9/site-packages/keras/engine/training.py\", line 2015, in run_step  **\n        outputs = model.predict_step(data)\n    File \"/Users/kuzmatsukanov/opt/anaconda3/lib/python3.9/site-packages/keras/engine/training.py\", line 1983, in predict_step\n        return self(x, training=False)\n    File \"/Users/kuzmatsukanov/opt/anaconda3/lib/python3.9/site-packages/keras/utils/traceback_utils.py\", line 70, in error_handler\n        raise e.with_traceback(filtered_tb) from None\n    File \"/Users/kuzmatsukanov/opt/anaconda3/lib/python3.9/site-packages/keras/engine/input_spec.py\", line 232, in assert_input_compatibility\n        raise ValueError(\n\n    ValueError: Exception encountered when calling layer \"resnet50\" \"                 f\"(type Functional).\n    \n    Input 0 of layer \"conv1_pad\" is incompatible with the layer: expected ndim=4, found ndim=3. Full shape received: (32, 224, 3)\n    \n    Call arguments received by layer \"resnet50\" \"                 f\"(type Functional):\n      • inputs=tf.Tensor(shape=(32, 224, 3), dtype=float32)\n      • training=False\n      • mask=None\n"
     ]
    }
   ],
   "source": [
    "resnet_feature_encoder.predict(input_img)"
   ]
  },
  {
   "cell_type": "code",
   "execution_count": null,
   "id": "9924bfd2-6098-403d-8380-5c011af162ec",
   "metadata": {},
   "outputs": [],
   "source": []
  },
  {
   "cell_type": "code",
   "execution_count": null,
   "id": "3c81d8bd-38d0-4261-acc3-8f4adbb67a82",
   "metadata": {},
   "outputs": [],
   "source": []
  }
 ],
 "metadata": {
  "kernelspec": {
   "display_name": "Python 3 (ipykernel)",
   "language": "python",
   "name": "python3"
  },
  "language_info": {
   "codemirror_mode": {
    "name": "ipython",
    "version": 3
   },
   "file_extension": ".py",
   "mimetype": "text/x-python",
   "name": "python",
   "nbconvert_exporter": "python",
   "pygments_lexer": "ipython3",
   "version": "3.9.12"
  }
 },
 "nbformat": 4,
 "nbformat_minor": 5
}
